Workbook

Sheet Assumptions
A1: Indonesia | 1MW Heat-First Geothermal Enterprise
A3: PRODUCT AND SERVICE
A4: Product | B4: Geothermal heat services + electricity | D4: Heat-first model: primary revenue from coffee drying, cold storage and agro-processing using direct geothermal heat (based on Kamojang GCP model). Secondary revenue from 1 MW binary electricity generation for local community and PLN.
A5: Binary generator size | B5: 1 | C5: MW | D5: Small modular binary (ORC) unit. Sized to match local demand. Uses lower-enthalpy resources
A6: Number of units | B6: 1 | C6: units | D6: Phase 1 deployment. Can add units if heat demand and resource confirm.
A7: Total installed capacity | B7: =B5*B6 -> 1 | C7: MW | D7: Module size x number of units.
A8: Capacity factor | B8: 0.85 | D8: Based on geothermal benchmarks (80-90% typical, IEA/IRENA). 85% is global average.
A9: Annual generation (GWh) | B9: =B7*B8*8760/1000 -> 7.446 | C9: GWh | D9: Total capacity x CF x 8,760 hrs / 1,000.
A10: Households served | B10: 500 | C10: households | D10: Smaller service area matching heat-first approach. Located near geothermal resource in coffee-growing highland area (e.g. Pangalengan or Kamojang, West Java). Possibility of expanding as scale increases.
A11: Household consumption | B11: 1300 | C11: kWh/yr | D11: Approximate annual electricity use per household; based on Indonesia per-capita consumption (around 300/400) converted to household level.
A12: Community demand (GWh) | B12: =B10*B11/1000000 -> 0.65 | C12: GWh | D12: Households x consumption / 1,000,000.
A14: CAPEX
A15: Exploration & confirmation | B15: 500000 | C15: USD | D15: Lower cost: targeting known surface manifestations and hot springs in West Java (130+ documented). Less risky than deep exploration. West Java has 62.2 MWth documented direct-use potential.
A16: Drilling (per MW) | B16: 750000 | C16: USD/MW | D16: Shallower wells targeting medium-enthalpy resources (80-150C). Can use existing non-productive wells near known fields (Wayang Windu, Kamojang). Lower than $1.5M+/MW for deep production wells.
A17: Binary plant EPC (per MW) | B17: 2000000 | C17: USD/MW | D17: Small-scale binary (ORC) plant. Based on Castlerock Consulting estimates adapted for smaller scale.
A18: Heat infrastructure | B18: 1000000 | C18: USD | D18: Geothermal Dry House for coffee drying (Kamojang GCP model), absorption chiller for cold storage, heat exchangers, piping. This is the core of the heat-first enterprise.
A19: Local grid connection | B19: 300000 | C19: USD | D19: Smaller connection — serving local community, not long-distance PLN transmission.
A20: Environmental & social impact | B20: 200000 | C20: USD | D20: Required for permitting and financing; standard. Lower for smaller scale.
A21: Total CapEx | B21: =B15+B16*B7+B17*B7+B18+B19+B20 -> 4750000 | C21: USD | D21: ~80% lower CapEx than 5 MW electricity-first model ($24.5M).
A23: OPERATING COSTS (OPEX)
A24: Fixed O&M (per MW/yr) | B24: 100000 | C24: USD/MW/yr | D24: IRENA benchmark ($80k-120k/MW/yr).
A25: Insurance | B25: 50000 | C25: USD/yr | D25: Scaled for smaller plant.
A26: Land lease & community payments | B26: 50000 | C26: USD/yr | D26: Compensation to local stakeholders; social license.
A27: Management & admin | B27: 100000 | C27: USD/yr | D27: Staffing for heat facility + plant management. Could be local hires. Not 100% sure. Might be lower?
A28: Heat facility operations | B28: 75000 | C28: USD/yr | D28: Running costs for drying facility, cold storage, absorption chiller. New line for heat-first model.
A29: Variable OpEx | B29: 25000 | C29: USD/yr | D29: Buffer
A30: Total OpEx | B30: =B24*B7+B25+B26+B27+B28+B29 -> 400000 | C30: USD/yr
A32: FINANCING & COST OF CAPITAL
A33: Debt share | B33: 0.7 | D33: Typical project finance structure.
A34: Equity share | B34: 0.3 | D34: Developer/investor contribution.
A35: Senior debt interest rate | B35: 0.07 | D35: Concessional finance benchmarks (ADB, World Bank).
A36: Loan length | B36: 15 | C36: years | D36: Seems standard for geothermal.
A37: Target IRR | B37: 0.15 | D37: Expected return for private investors.
A38: WACC | B38: 0.08 | D38: Blended concessional + commercial capital.
A40: HEAT SERVICES REVENUE
A41: Coffee drying revenue | B41: 75000 | C41: USD/yr | D41: Based on Kamojang GCP model (Pertamina). GCP processes 20+ tons/season with 80+ farmer partners. Target: 100-150 tons/yr. Geothermal Dry House cuts drying time 3x (full wash: 7-10 days to 2-4 days). Higher quality = premium pricing. ~$0.50/kg fee. Pangalengan produced 6,499 tons coffee in 2014
A42: Cold storage revenue | B42: 50000 | C42: USD/yr | D42: Absorption chiller powered by geothermal heat. Reduces post-harvest losses from 30-40% to <10% (FAO). ~50-ton capacity. Farmers can sell when prices are better, not at harvest glut. Strong social impact.
A43: Agro-processing & other | B43: 50000 | C43: USD/yr | D43: Tea drying (Wayang Windu precedent), cocoa, spice drying, rice drying. Also egg-hatching incubators, mushroom cultivation sterilization (already at Kamojang).
A44: Total heat services revenue | B44: =B41+B42+B43 -> 175000 | C44: USD/yr
A46: ELECTRICITY REVENUE
...

Sheet Financing Plan
A1: Financing Plan
A3: Financing Item | B3: Amount (USD) | C3: Notes
A4: CAPITAL STACK
A5: Total CapEx | B5: =Assumptions!B21 -> 4750000 | C5: Total project capital requirement before grant reduction
A6: Less: Exploration grant | B6: =-Assumptions!B62 -> -500000
A7: Net CapEx to finance | B7: =B5+B6 -> 4250000
A8: Debt (70%) | B8: =B7*Assumptions!B33 -> 2975000 | C8: Assumes standard project finance debt share
A9: Concessional loan | B9: =Assumptions!B63 -> 2000000 | C9: Lower interest rate portion from development finance institutions
A10: Commercial debt | B10: =B8-B9 -> 975000
A11: Equity (30%) | B11: =B7*Assumptions!B34 -> 1275000 | C11: Developer/investor equity contribution
A13: DEBT SERVICE
A14: Blended interest rate | B14: =IF(B8=0,0,(B9*(Assumptions!B35-Assumptions!B67)+B10*Assumptions!B35)/B8) -> 0.056554622
A15: Loan term | B15: =Assumptions!B36 -> 15
A16: Annual debt payment | B16: =-PMT(B14,B15,B8) -> 299456.01 | C16: Annual debt service using simple PMT formula
A18: YEAR 1 RETURN
A19: Year 1 Total Revenue | B19: =Assumptions!B55+Assumptions!B66 -> 917888 | C19: Heat + electricity + carbon.
A20: Year 1 OpEx | B20: =Assumptions!B30 -> 400000
A21: Year 1 EBITDA | B21: =B19-B20 -> 517888
A22: Year 1 Net Income | B22: =B21-B16 -> 218431.99
A23: Cash-on-Cash Return | B23: =IF(B11=0,0,B22/B11) -> 0.17131921

Sheet Break-Even
A1: Break-Even Analysis
A3: Metric | B3: Value | C3: Unit | D3: Notes
A4: KEY METRICS
A5: Annual OpEx | B5: =Assumptions!B30 -> 400000 | C5: USD/yr | G5: NOTES
A6: Total CapEx | B6: =Assumptions!B21 -> 4750000 | C6: USD | G6: Heat-first = lower CapEx, stronger social impact per dollar invested.
A7: Net CapEx (after grant) | B7: ='Financing Plan'!B7 -> 4250000 | C7: USD | G7: Coffee drying (Kamojang GCP) already proven in West Java by Pertamina.
A8: Year 1 Revenue (incl carbon) | B8: ='Financing Plan'!B19 -> 917888 | C8: USD | G8: Cold storage reduces post-harvest losses from 30-40% to <10% (FAO).
A9: Year 1 EBITDA | B9: ='Financing Plan'!B21 -> 517888 | C9: USD | D9: Year 1 net income before financing | G9: Electricity is a side benefit from the same geothermal resource.
A10: Simple payback (net CapEx) | B10: =IF(B9<=0,"N/A",B7/B9) -> 8.2064076 | C10: Years | D10: Net CapEx / Year 1 EBITDA (simplified, no escalation)
A11: Payback on equity | B11: =IF('Pro Forma P&L'!C17<=0,"Neg",('Financing Plan'!B11/'Pro Forma P&L'!C17)) -> 5.837057 | C11: Years | D11: Equity invested / Year 1 net income after debt
A12: Equity breakeven year | B12: =IF('Pro Forma P&L'!C22>=0,1,IF('Pro Forma P&L'!D22>=0,2,IF('Pro Forma P&L'!E22>=0,3,IF('Pro Forma P&L'!F22>=0,4,IF('Pro Forma P&L'!G22>=0,5,IF('Pro Forma P&L'!H22>=0,6,IF('Pro Forma P&L'!I22>=0,7,IF('Pro Forma P&L'!J22>=0,8,IF('Pro Forma P&L'!K22>=0,9,IF('Pro Forma P&L'!L22>=0,10,IF('Pro Forma P&L'!M22>=0,11,IF('Pro Forma P&L'!N22>=0,12,IF('Pro Forma P&L'!O22>=0,13,IF('Pro Forma P&L'!P22>=0,14,IF('Pro Forma P&L'!Q22>=0,15,IF('Pro Forma P&L'!R22>=0,16,IF('Pro Forma P&L'!S22>=0,17,IF('Pro Forma P&L'!T22>=0,18,IF('Pro Forma P&L'!U22>=0,19,IF('Pro Forma P&L'!V22>=0,20,IF('Pro Forma P&L'!W22>=0,21,IF('Pro Forma P&L'!X22>=0,22,IF('Pro Forma P&L'!Y22>=0,23,IF('Pro Forma P&L'!Z22>=0,24,IF('Pro Forma P&L'!AA22>=0,25,IF('Pro Forma P&L'!AB22>=0,26,IF('Pro Forma P&L'!AC22>=0,27,IF('Pro Forma P&L'!AD22>=0,28,IF('Pro Forma P&L'!AE22>=0,29,IF('Pro Forma P&L'!AF22>=0,30,"30+")))))))))))))))))))))))))))))) -> 6 | C12: Year | D12: First year cumulative equity cash flow turns positive
A14: VS 5 MW ELECTRICITY-FIRST MODEL
A15: 5 MW model CapEx | B15: 24500000
A16: This model CapEx | B16: =Assumptions!B21 -> 4750000
A17: CapEx reduction | B17: =1-B16/B15 -> 0.80612245

Sheet Pro Forma P&L
A1: Pro Forma — Heat-First 1MW (30-Year)
A2: Field | B2: Unit | C2: Year 1 | D2: Year 2 | E2: Year 3 | F2: Year 4 | G2: Year 5 | H2: Year 6 | I2: Year 7 | J2: Year 8 | K2: Year 9 | L2: Year 10 | M2: Year 11 | N2: Year 12 | O2: Year 13 | P2: Year 14 | Q2: Year 15 | R2: Year 16 | S2: Year 17 | T2: Year 18 | U2: Year 19 | V2: Year 20 | W2: Year 21 | X2: Year 22 | Y2: Year 23 | Z2: Year 24 | AA2: Year 25 | AB2: Year 26 | AC2: Year 27 | AD2: Year 28 | AE2: Year 29 | AF2: Year 30
J3: REVENUE
A4: Generation (GWh) | B4: GWh | C4: =Assumptions!B9 -> 7.446 | D4: =C4*(1-Assumptions!$B$72) -> 7.40877 | E4: =D4*(1-Assumptions!$B$72) -> 7.3717261 | F4: =E4*(1-Assumptions!$B$72) -> 7.3348675 | G4: =F4*(1-Assumptions!$B$72) -> 7.2981932 | H4: =G4*(1-Assumptions!$B$72) -> 7.2617022 | I4: =H4*(1-Assumptions!$B$72) -> 7.2253937 | J4: =I4*(1-Assumptions!$B$72) -> 7.1892667 | K4: =J4*(1-Assumptions!$B$72) -> 7.1533204 | ... AF4: =AE4*(1-Assumptions!$B$72) -> 6.4386138
A5: Electricity Revenue | B5: USD | C5: =Assumptions!B54 -> 698212 | D5: =C5*(1+Assumptions!$B$71)*(1-Assumptions!$B$72) -> 708615.36 | E5: =D5*(1+Assumptions!$B$71)*(1-Assumptions!$B$72) -> 719173.73 | F5: =E5*(1+Assumptions!$B$71)*(1-Assumptions!$B$72) -> 729889.42 | G5: =F5*(1+Assumptions!$B$71)*(1-Assumptions!$B$72) -> 740764.77 | H5: =G5*(1+Assumptions!$B$71)*(1-Assumptions!$B$72) -> 751802.16 | I5: =H5*(1+Assumptions!$B$71)*(1-Assumptions!$B$72) -> 763004.02 | J5: =I5*(1+Assumptions!$B$71)*(1-Assumptions!$B$72) -> 774372.78 | K5: =J5*(1+Assumptions!$B$71)*(1-Assumptions!$B$72) -> 785910.93 | ... AF5: =AE5*(1+Assumptions!$B$71)*(1-Assumptions!$B$72) -> 1072165
A6: Heat Services Revenue | B6: USD | C6: =Assumptions!B44 -> 175000 | D6: =C6*(1+Assumptions!$B$74) -> 180250 | E6: =D6*(1+Assumptions!$B$74) -> 185657.5 | F6: =E6*(1+Assumptions!$B$74) -> 191227.23 | G6: =F6*(1+Assumptions!$B$74) -> 196964.04 | H6: =G6*(1+Assumptions!$B$74) -> 202872.96 | I6: =H6*(1+Assumptions!$B$74) -> 208959.15 | J6: =I6*(1+Assumptions!$B$74) -> 215227.93 | K6: =J6*(1+Assumptions!$B$74) -> 221684.76 | ... AF6: =AE6*(1+Assumptions!$B$74) -> 412398.96
A7: Carbon Credit Revenue | B7: USD | C7: =C4*1000*Assumptions!$B$65*Assumptions!$B$64 -> 44676 | D7: =D4*1000*Assumptions!$B$65*Assumptions!$B$64 -> 44452.62 | E7: =E4*1000*Assumptions!$B$65*Assumptions!$B$64 -> 44230.357 | F7: =F4*1000*Assumptions!$B$65*Assumptions!$B$64 -> 44009.205 | G7: =G4*1000*Assumptions!$B$65*Assumptions!$B$64 -> 43789.159 | H7: =H4*1000*Assumptions!$B$65*Assumptions!$B$64 -> 43570.213 | I7: =I4*1000*Assumptions!$B$65*Assumptions!$B$64 -> 43352.362 | J7: =J4*1000*Assumptions!$B$65*Assumptions!$B$64 -> 43135.6 | ... AF7: =AF4*1000*Assumptions!$B$65*Assumptions!$B$64 -> 38631.683
A8: TOTAL REVENUE | B8: USD | C8: =C5+C6+C7 -> 917888 | D8: =D5+D6+D7 -> 933317.98 | E8: =E5+E6+E7 -> 949061.58 | F8: =F5+F6+F7 -> 965125.85 | G8: =G5+G6+G7 -> 981517.97 | H8: =H5+H6+H7 -> 998245.34 | I8: =I5+I6+I7 -> 1015315.5 | J8: =J5+J6+J7 -> 1032736.3 | ... AF8: =AF5+AF6+AF7 -> 1523195.7
J10: OPERATING EXPENSES
A11: Fixed O&M | B11: USD | C11: =Assumptions!B24*Assumptions!B7 -> 100000 | D11: =C11*(1+Assumptions!$B$73) -> 102000 | E11: =D11*(1+Assumptions!$B$73) -> 104040 | F11: =E11*(1+Assumptions!$B$73) -> 106120.8 | G11: =F11*(1+Assumptions!$B$73) -> 108243.22 | H11: =G11*(1+Assumptions!$B$73) -> 110408.08 | I11: =H11*(1+Assumptions!$B$73) -> 112616.24 | J11: =I11*(1+Assumptions!$B$73) -> 114868.57 | K11: =J11*(1+Assumptions!$B$73) -> 117165.94 | ... AF11: =AE11*(1+Assumptions!$B$73) -> 177584.47
A12: Variable, Admin & Heat Ops | B12: USD | C12: =Assumptions!B25+Assumptions!B26+Assumptions!B27+Assumptions!B28+Assumptions!B29 -> 300000 | D12: =C12*(1+Assumptions!$B$73) -> 306000 | E12: =D12*(1+Assumptions!$B$73) -> 312120 | F12: =E12*(1+Assumptions!$B$73) -> 318362.4 | G12: =F12*(1+Assumptions!$B$73) -> 324729.65 | H12: =G12*(1+Assumptions!$B$73) -> 331224.24 | I12: =H12*(1+Assumptions!$B$73) -> 337848.73 | J12: =I12*(1+Assumptions!$B$73) -> 344605.7 | K12: =J12*(1+Assumptions!$B$73) -> 351497.81 | ... AF12: =AE12*(1+Assumptions!$B$73) -> 532753.41
A13: TOTAL OPEX | B13: USD | C13: =C11+C12 -> 400000 | D13: =D11+D12 -> 408000 | E13: =E11+E12 -> 416160 | F13: =F11+F12 -> 424483.2 | G13: =G11+G12 -> 432972.86 | H13: =H11+H12 -> 441632.32 | I13: =I11+I12 -> 450464.97 | J13: =J11+J12 -> 459474.27 | ... AF13: =AF11+AF12 -> 710337.88
A15: EBITDA | B15: USD | C15: =C8-C13 -> 517888 | D15: =D8-D13 -> 525317.98 | E15: =E8-E13 -> 532901.58 | F15: =F8-F13 -> 540642.65 | G15: =G8-G13 -> 548545.11 | H15: =H8-H13 -> 556613.02 | I15: =I8-I13 -> 564850.56 | J15: =J8-J13 -> 573262.04 | ... AF15: =AF8-AF13 -> 812857.78
A16: Debt Service | B16: USD | C16: =IF(1<=Assumptions!$B$36,'Financing Plan'!$B$16,0) -> 299456.01 | D16: =IF(2<=Assumptions!$B$36,'Financing Plan'!$B$16,0) -> 299456.01 | E16: =IF(3<=Assumptions!$B$36,'Financing Plan'!$B$16,0) -> 299456.01 | F16: =IF(4<=Assumptions!$B$36,'Financing Plan'!$B$16,0) -> 299456.01 | G16: =IF(5<=Assumptions!$B$36,'Financing Plan'!$B$16,0) -> 299456.01 | H16: =IF(6<=Assumptions!$B$36,'Financing Plan'!$B$16,0) -> 299456.01 | I16: =IF(7<=Assumptions!$B$36,'Financing Plan'!$B$16,0) -> 299456.01 | J16: =IF(8<=Assumptions!$B$36,'Financing Plan'!$B$16,0) -> 299456.01 | K16: =IF(9<=Assumptions!$B$36,'Financing Plan'!$B$16,0) -> 299456.01 | L16: =IF(10<=Assumptions!$B$36,'Financing Plan'!$B$16,0) -> 299456.01 | M16: =IF(11<=Assumptions!$B$36,'Financing Plan'!$B$16,0) -> 299456.01 | N16: =IF(12<=Assumptions!$B$36,'Financing Plan'!$B$16,0) -> 299456.01 | O16: =IF(13<=Assumptions!$B$36,'Financing Plan'!$B$16,0) -> 299456.01 | P16: =IF(14<=Assumptions!$B$36,'Financing Plan'!$B$16,0) -> 299456.01 | Q16: =IF(15<=Assumptions!$B$36,'Financing Plan'!$B$16,0) -> 299456.01 | R16: =IF(16<=Assumptions!$B$36,'Financing Plan'!$B$16,0) -> 0 | S16: =IF(17<=Assumptions!$B$36,'Financing Plan'!$B$16,0) -> 0 | T16: =IF(18<=Assumptions!$B$36,'Financing Plan'!$B$16,0) -> 0 | U16: =IF(19<=Assumptions!$B$36,'Financing Plan'!$B$16,0) -> 0 | V16: =IF(20<=Assumptions!$B$36,'Financing Plan'!$B$16,0) -> 0 | W16: =IF(21<=Assumptions!$B$36,'Financing Plan'!$B$16,0) -> 0 | X16: =IF(22<=Assumptions!$B$36,'Financing Plan'!$B$16,0) -> 0 | Y16: =IF(23<=Assumptions!$B$36,'Financing Plan'!$B$16,0) -> 0 | Z16: =IF(24<=Assumptions!$B$36,'Financing Plan'!$B$16,0) -> 0 | AA16: =IF(25<=Assumptions!$B$36,'Financing Plan'!$B$16,0) -> 0 | AB16: =IF(26<=Assumptions!$B$36,'Financing Plan'!$B$16,0) -> 0 | AC16: =IF(27<=Assumptions!$B$36,'Financing Plan'!$B$16,0) -> 0 | AD16: =IF(28<=Assumptions!$B$36,'Financing Plan'!$B$16,0) -> 0 | AE16: =IF(29<=Assumptions!$B$36,'Financing Plan'!$B$16,0) -> 0 | AF16: =IF(30<=Assumptions!$B$36,'Financing Plan'!$B$16,0) -> 0
A17: NET INCOME | B17: USD | C17: =C15-C16 -> 218431.99 | D17: =D15-D16 -> 225861.97 | E17: =E15-E16 -> 233445.58 | F17: =F15-F16 -> 241186.64 | G17: =G15-G16 -> 249089.1 | H17: =H15-H16 -> 257157.01 | I17: =I15-I16 -> 265394.56 | J17: =J15-J16 -> 273806.03 | ... AF17: =AF15-AF16 -> 812857.78
J19: CASH FLOW ANALYSIS
A20: Equity Invested (Year 0) | B20: USD | C20: =-'Financing Plan'!B11 -> -1275000 | D20: 0 | E20: 0 | F20: 0 | G20: 0 | H20: 0 | I20: 0 | J20: 0 | K20: 0 | L20: 0 | M20: 0 | N20: 0 | O20: 0 | P20: 0 | Q20: 0 | R20: 0 | S20: 0 | T20: 0 | U20: 0 | V20: 0 | W20: 0 | X20: 0 | Y20: 0 | Z20: 0 | AA20: 0 | AB20: 0 | AC20: 0 | AD20: 0 | AE20: 0 | AF20: 0
A21: Annual Cash Flow to Equity | B21: USD | C21: =C17 -> 218431.99 | D21: =D17 -> 225861.97 | E21: =E17 -> 233445.58 | F21: =F17 -> 241186.64 | G21: =G17 -> 249089.1 | H21: =H17 -> 257157.01 | I21: =I17 -> 265394.56 | J21: =J17 -> 273806.03 | ... AF21: =AF17 -> 812857.78
A22: Cumulative Cash Flow | B22: USD | C22: =C20+C21 -> -1056568 | D22: =C22+D21 -> -830706.03 | E22: =D22+E21 -> -597260.45 | F22: =E22+F21 -> -356073.81 | G22: =F22+G21 -> -106984.71 | H22: =G22+H21 -> 150172.3 | I22: =H22+I21 -> 415566.85 | J22: =I22+J21 -> 689372.88 | K22: =J22+K21 -> 971768.74 | ... AF22: =AE22+AF21 -> 13748804
A23: EBITDA Margin | B23: % | C23: =IF(C8=0,0,C15/C8) -> 0.56421699 | D23: =IF(D8=0,0,D15/D8) -> 0.56284995 | E23: =IF(E8=0,0,E15/E8) -> 0.56150369 | F23: =IF(F8=0,0,F15/F8) -> 0.56017839 | G23: =IF(G8=0,0,G15/G8) -> 0.55887424 | H23: =IF(H8=0,0,H15/H8) -> 0.5575914 | I23: =IF(I8=0,0,I15/I8) -> 0.55633007 | J23: =IF(J8=0,0,J15/J8) -> 0.55509043 | ... AF23: =IF(AF8=0,0,AF15/AF8) -> 0.5336529
A24: DSCR | B24: x | C24: =IF(C16=0,0,C15/C16) -> 1.7294293 | D24: =IF(D16=0,0,D15/D16) -> 1.7542409 | E24: =IF(E16=0,0,E15/E16) -> 1.7795655 | F24: =IF(F16=0,0,F15/F16) -> 1.8054159 | G24: =IF(G16=0,0,G15/G16) -> 1.8318053 | H24: =IF(H16=0,0,H15/H16) -> 1.8587472 | I24: =IF(I16=0,0,I15/I16) -> 1.8862556 | J24: =IF(J16=0,0,J15/J16) -> 1.9143448 | ... AF24: =IF(AF16=0,0,AF15/AF16) -> 0
A25: Heat % of Revenue | B25: % | C25: =IF(C8=0,0,C6/C8) -> 0.19065507 | D25: =IF(D8=0,0,D6/D8) -> 0.19312818 | E25: =IF(E8=0,0,E6/E8) -> 0.19562218 | F25: =IF(F8=0,0,F6/F8) -> 0.19813709 | G25: =IF(G8=0,0,G6/G8) -> 0.20067288 | H25: =IF(H8=0,0,H6/H8) -> 0.20322956 | I25: =IF(I8=0,0,I6/I8) -> 0.20580711 | J25: =IF(J8=0,0,J6/J8) -> 0.2084055 | ... AF25: =IF(AF8=0,0,AF6/AF8) -> 0.27074589
H27: ✓ EQUITY BREAKEVEN | R27: ✓ LOAN REPAID
